Workbook
Name Slicer_Content_Category: #N/A

Sheet Original Sheet
A1: Pack Name | B1: Pack Type | C1: Release Date | D1: Release Year | E1: Launch Price USD | F1: Currently Free? | G1: Simulation-Rich vs. Aesthetic | H1: Primary Impact
A2: Get to Work | B2: Expansion Pack | C2: 42094 | D2: =YEAR(C2) -> 2015 | E2: 39.99 | F2: No | G2: Simulation-Rich | H2: Active Careers & Aliens (Major system change).
A3: Get Together | B3: Expansion Pack | C3: 42346 | D3: =YEAR(C3) -> 2015 | E3: 39.99 | F3: No | G3: Simulation-Rich | H3: Club System (Massive social engine upgrade).
A4: City Living | B4: Expansion Pack | C4: 42675 | D4: =YEAR(C4) -> 2016 | E4: 39.99 | F4: No | G4: Simulation-Rich | H4: Apartments (System) + Culture/Festivals (Aesthetic).
A5: Cats & Dogs | B5: Expansion Pack | C5: 43049 | D5: =YEAR(C5) -> 2017 | E5: 39.99 | F5: No | G5: Simulation-Rich | H5: Entirely new AI for pets and Vet career.
A6: Seasons | B6: Expansion Pack | C6: 43273 | D6: =YEAR(C6) -> 2018 | E6: 39.99 | F6: No | G6: Simulation-Rich | H6: Global weather and calendar (The ultimate "Life" pack).
A7: Get Famous | B7: Expansion Pack | C7: 43420 | D7: =YEAR(C7) -> 2018 | E7: 39.99 | F7: No | G7: Simulation-Rich | H7: Fame/Reputation system + tons of "lifestyle" decor.
A8: Island Living | B8: Expansion Pack | C8: 43637 | D8: =YEAR(C8) -> 2019 | E8: 39.99 | F8: No | G8: Simulation-Rich | H8: Mostly "vacation vibes" and world-building; weak gameplay.
A9: Discover University | B9: Expansion Pack | C9: 43784 | D9: =YEAR(C9) -> 2019 | E9: 39.99 | F9: No | G9: Simulation-Rich | H9: Education system and degree-based career paths.
A10: Eco Lifestyle | B10: Expansion Pack | C10: 43987 | D10: =YEAR(C10) -> 2020 | E10: 39.99 | F10: No | G10: Simulation-Rich | H10: Neighborhood Action Plans (Gameplay) + Crafting (Aesthetic).
A11: Snowy Escape | B11: Expansion Pack | C11: 44148 | D11: =YEAR(C11) -> 2020 | E11: 39.99 | F11: No | G11: Simulation-Rich | H11: Lifestyles/Sentiments (Light) + heavy focus on "vibe" items.
A12: Cottage Living | B12: Expansion Pack | C12: 44399 | D12: =YEAR(C12) -> 2021 | E12: 39.99 | F12: No | G12: Simulation-Rich | H12: Farming/Simple Living (System) + Country Decor.
A13: High School Years | B13: Expansion Pack | C13: 44770 | D13: =YEAR(C13) -> 2022 | E13: 39.99 | F13: No | G13: Simulation-Rich | H13: Active High School (System) + Heavy focus on "Trendi" (Lifestyle).
... A100: The Sims 4 Base Game | B100: Base Game | C100: 41884 | D100: =YEAR(C100) -> 2014 | E100: 59.99 | F100: Yes | G100: Simulation-Rich | H100: Introduces core life-simulations systems
B102: =SUM(E55:E99) -> 228.55
E103: =SUM(E2:E100) -> 1568.01

Sheet DLC Master Log
A1: Pack Name | B1: Pack Type | C1: Release Date | D1: Release Year | E1: Launch Price USD | F1: Currently Free? | G1: Content Category | H1: Primary Impact
A2: Get to Work | B2: Expansion Pack | C2: 42094 | D2: =YEAR(C2) -> 2015 | E2: 39.99 | F2: No | G2: Simulation-Rich | H2: Active Careers & Aliens (Major system change).
A3: Get Together | B3: Expansion Pack | C3: 42346 | D3: =YEAR(C3) -> 2015 | E3: 39.99 | F3: No | G3: Simulation-Rich | H3: Club System (Massive social engine upgrade).
A4: City Living | B4: Expansion Pack | C4: 42675 | D4: =YEAR(C4) -> 2016 | E4: 39.99 | F4: No | G4: Simulation-Rich | H4: Apartments (System) + Culture/Festivals (Aesthetic).
A5: Cats & Dogs | B5: Expansion Pack | C5: 43049 | D5: =YEAR(C5) -> 2017 | E5: 39.99 | F5: No | G5: Simulation-Rich | H5: Entirely new AI for pets and Vet career.
A6: Seasons | B6: Expansion Pack | C6: 43273 | D6: =YEAR(C6) -> 2018 | E6: 39.99 | F6: No | G6: Simulation-Rich | H6: Global weather and calendar (The ultimate "Life" pack).
A7: Get Famous | B7: Expansion Pack | C7: 43420 | D7: =YEAR(C7) -> 2018 | E7: 39.99 | F7: No | G7: Simulation-Rich | H7: Fame/Reputation system + tons of "lifestyle" decor.
A8: Island Living | B8: Expansion Pack | C8: 43637 | D8: =YEAR(C8) -> 2019 | E8: 39.99 | F8: No | G8: Simulation-Rich | H8: Mostly "vacation vibes" and world-building; weak gameplay.
A9: Discover University | B9: Expansion Pack | C9: 43784 | D9: =YEAR(C9) -> 2019 | E9: 39.99 | F9: No | G9: Simulation-Rich | H9: Education system and degree-based career paths.
A10: Eco Lifestyle | B10: Expansion Pack | C10: 43987 | D10: =YEAR(C10) -> 2020 | E10: 39.99 | F10: No | G10: Simulation-Rich | H10: Neighborhood Action Plans (Gameplay) + Crafting (Aesthetic).
A11: Snowy Escape | B11: Expansion Pack | C11: 44148 | D11: =YEAR(C11) -> 2020 | E11: 39.99 | F11: No | G11: Simulation-Rich | H11: Lifestyles/Sentiments (Light) + heavy focus on "vibe" items.
A12: Cottage Living | B12: Expansion Pack | C12: 44399 | D12: =YEAR(C12) -> 2021 | E12: 39.99 | F12: No | G12: Simulation-Rich | H12: Farming/Simple Living (System) + Country Decor.
A13: High School Years | B13: Expansion Pack | C13: 44770 | D13: =YEAR(C13) -> 2022 | E13: 39.99 | F13: No | G13: Simulation-Rich | H13: Active High School (System) + Heavy focus on "Trendi" (Lifestyle).
... A100: The Sims 4 Base Game | B100: Base Game | C100: 41884 | D100: =YEAR(C100) -> 2014 | E100: 59.99 | F100: Yes | G100: Simulation-Rich | H100: Introduces core life-simulations systems

Sheet Fan Requests
A1: Feature Name | B1: Description | C1: Earliest Verified Request | D1: Current Status | E1: Year Added | F1: Years Ignored | G1: Impact on Simulation
A2: Open World | B2: Freedom to move between lots and neighborhoods without loading screens | C2: 2014 | D2: Never Added | E2: N/A | F2: =IF(D2="Never Added", YEAR(TODAY())-C2, IF(D2="Partially Added",YEAR(TODAY())-C2,E2-C2)) -> 12 | G2: HIGH
A3: Color Wheel/ create-a-Style | B3: A tool allowing players to recolor any objects, clothing, or furniture in any custom color | C3: 2014 | D3: Never Added | E3: N/A | F3: =IF(D3="Never Added", YEAR(TODAY())-C3, IF(D3="Partially Added",YEAR(TODAY())-C3,E3-C3)) -> 12 | G3: MEDIUM
A4: Drivable Cars | B4: Functional vehicles Sims can own, drive, and use to travel | C4: 2014 | D4: Never Added | E4: N/A | F4: =IF(D4="Never Added", YEAR(TODAY())-C4, IF(D4="Partially Added",YEAR(TODAY())-C4,E4-C4)) -> 12 | G4: MEDIUM
A5: Burglars/Danger Mechanics | B5: An NPC that breaks into Sims' houses to steal items | C5: 2014 | D5: Added Late | E5: 2025 | F5: =IF(D5="Never Added", YEAR(TODAY())-C5, IF(D5="Partially Added",YEAR(TODAY())-C5,E5-C5)) -> 11 | G5: MEDIUM
A6: Pools | B6: The ability to build and use swimming pools. Launched without but added months later. | C6: 2014 | D6: Added Late | E6: 2014 | F6: =IF(D6="Never Added", YEAR(TODAY())-C6, IF(D6="Partially Added",YEAR(TODAY())-C6,E6-C6)) -> 0 | G6: LOW
A7: Toddlers | B7: A fully playable toddler life stage with unique interactions, skills and needs | C7: 2014 | D7: Added Late | E7: 2017 | F7: =IF(D7="Never Added", YEAR(TODAY())-C7, IF(D7="Partially Added",YEAR(TODAY())-C7,E7-C7)) -> 3 | G7: HIGH
A8: Genetics Improvement | B8: Children inheriting dominant and recessive traits and facial features across multiple generations | C8: 2014 | D8: Partially Added | E8: 2023 | F8: =IF(D8="Never Added", YEAR(TODAY())-C8, IF(D8="Partially Added",YEAR(TODAY())-C8,E8-C8)) -> 12 | G8: HIGH
A9: Spiral Staircases | B9: Curved and spiral staircase options | C9: 2014 | D9: Never Added | E9: N/A | F9: =IF(D9="Never Added", YEAR(TODAY())-C9, IF(D9="Partially Added",YEAR(TODAY())-C9,E9-C9)) -> 12 | G9: LOW
A10: Family tree System | B10: A full visual family tree showing generational history and relationship betweeb Sims | C10: 2014 | D10: Partially Added | E10: 2026 | F10: =IF(D10="Never Added", YEAR(TODAY())-C10, IF(D10="Partially Added",YEAR(TODAY())-C10,E10-C10)) -> 12 | G10: MEDIUM
A11: Temerature System (base game) | B11: Weather and temperature effects as a base game feature | C11: 2014 | D11: Never Added | E11: N/A | F11: =IF(D11="Never Added", YEAR(TODAY())-C11, IF(D11="Partially Added",YEAR(TODAY())-C11,E11-C11)) -> 12 | G11: HIGH
A12: Story Progression | B12: Neighborhood Sims aging, getting jobs, marrying and having children without player intervention | C12: 2014 | D12: Partially Added | E12: 2021 | F12: =IF(D12="Never Added", YEAR(TODAY())-C12, IF(D12="Partially Added",YEAR(TODAY())-C12,E12-C12)) -> 12 | G12: HIGH
A13: Terrain Tools | B13: The ability to raise, lower, and sculpt terrain in lots | C13: 2014 | D13: Added Late | E13: 2018 | F13: =IF(D13="Never Added", YEAR(TODAY())-C13, IF(D13="Partially Added",YEAR(TODAY())-C13,E13-C13)) -> 4 | G13: LOW
A14: Curved Walls | B14: The ability to build curved and rounded walls in build mode | C14: 2014 | D14: Added Late | E14: 2022 | F14: =IF(D14="Never Added", YEAR(TODAY())-C14, IF(D14="Partially Added",YEAR(TODAY())-C14,E14-C14)) -> 8 | G14: LOW
A15: Attraction System | B15: A system where Sims feel genuine attraction/repulsion based on personality | C15: 2014 | D15: Added Late | E15: 2024 | F15: =IF(D15="Never Added", YEAR(TODAY())-C15, IF(D15="Partially Added",YEAR(TODAY())-C15,E15-C15)) -> 10 | G15: HIGH
A16: World Editor/ Create-a-World | B16: A tool allowing players to build and edit worlds and neighborhoods | C16: 2014 | D16: Never Added | E16: N/A | F16: =IF(D16="Never Added", YEAR(TODAY())-C16, IF(D16="Partially Added",YEAR(TODAY())-C16,E16-C16)) -> 12 | G16: HIGH
A17: Bands/Music Groups | B17: The ability for Sims to form bands and perform music together | C17: 2014 | D17: Never Added | E17: N/A | F17: =IF(D17="Never Added", YEAR(TODAY())-C17, IF(D17="Partially Added",YEAR(TODAY())-C17,E17-C17)) -> 12 | G17: MEDIUM
A18: Multiplayer/Visit Other Players' Worlds | B18: The ability for players to visut each other's worlds and play together in real time | C18: 2014 | D18: Never Added | E18: N/A | F18: =IF(D18="Never Added", YEAR(TODAY())-C18, IF(D18="Partially Added",YEAR(TODAY())-C18,E18-C18)) -> 12 | G18: HIGH

Sheet Feature & Cost Comparison
A1: Feature Category | B1: Feature Type | C1: Feature | D1: The Sims 3 Launch (2009) | E1: The Sims 4 Launch (2014) | F1: The Sims 4 Base Game Now (2026) | G1: The Sims 4 Full Game (2026) | H1: inZOI (2025) | I1: Paralives (2026)
A2: World & Navigation | B2: Core | C2: Open World | D2: YES | E2: NO | F2: NO | G2: NO | H2: YES | I2: YES
A3: World & Navigation | B3: Core | C3: Drivable Cars | D3: YES | E3: NO | F3: NO | G3: NO | H3: YES | I3: NO
A4: World & Navigation | B4: Expected | C4: Weather/Seasons (Base Game) | D4: YES | E4: NO | F4: NO | G4: NO | H4: YES | I4: NO
A5: World & Navigation | B5: Expected | C5: World Editor/ Create-a-World | D5: YES | E5: NO | F5: NO | G5: NO | H5: PARTIAL | I5: YES
A6: Build Mode | B6: Core | C6: Color Wheel/Recolor Tool | D6: YES | E6: NO | F6: NO | G6: NO | H6: YES | I6: YES
A7: Build Mode | B7: Expected | C7: Terrain Tools | D7: YES | E7: NO | F7: YES | G7: YES | H7: YES | I7: YES
A8: Build Mode | B8: Bonus | C8: Curved Walls | D8: NO | E8: NO | F8: YES | G8: YES | H8: NO | I8: YES
A9: Build Mode | B9: Expected | C9: Spiral Staircases | D9: YES | E9: NO | F9: NO | G9: NO | H9: YES | I9: YES
A10: Build Mode | B10: Expected | C10: Grid-Free Object Placement | D10: YES | E10: NO | F10: PARTIAL | G10: PARTIAL | H10: YES | I10: YES
A11: Build Mode | B11: Expected | C11: Pools | D11: YES | E11: NO | F11: YES | G11: YES | H11: YES | I11: NO
A12: Life Simulation | B12: Core | C12: Complete Life Stages | D12: PARTIAL | E12: NO | F12: YES | G12: YES | H12: PARTIAL | I12: PARTIAL
... A24: Pets | B24: Expected | C24: Pets | D24: NO | E24: NO | F24: NO | G24: YES | H24: NO | I24: NO
C26: Base Game Price (Launch) | D26: 49.99 | E26: 59.99 | F26: FREE | G26: FREE | H26: 39.99 | I26: 39.99
C27: Total DLC Packs(excluding base game) | D27: 20 | E27: 0 | F27: 0 | G27: 98 | H27: 0 | I27: 0
C28: Total DLC Cost (excluding base game) | D28: 609.8 | E28: 0 | F28: 0 | G28: 1508.02 | H28: 0 | I28: 0
C29: Total Cost to Own (including base game) | D29: 659.79 | E29: 59.99 | F29: 0 | G29: 1568.01 | H29: 39.99 | I29: 39.99

Sheet Content Strategy Analysis
A1: Year | B1: Aesthetic Count | C1: Simulation-Rich Count | D1: Total Packs | E1: % Aesthetic | F1: % Simulation-Rich | G1: Total Aesthetic Retail Value | H1: Total Simulation-Rich Retail Value | I1: Cumulative Aesthetic Retail Value | J1: Cumulative Simulation-Rich Retail Value | K1: Expansion Pack Count | L1: Game Pack Count | M1: Stuff Pack Count | N1: Kit Count | O1: Total Kit Retail Value
A2: 2015 | B2: =COUNTIFS('DLC Master Log'!D:D,A2,'DLC Master Log'!G:G,"Aesthetic") -> 5 | C2: =COUNTIFS('DLC Master Log'!D:D,A2,'DLC Master Log'!G:G,"Simulation-Rich") -> 3 | D2: =B2+C2 -> 8 | E2: =IFERROR(B2/D2,0) -> 0.625 | F2: =IFERROR(C2/D2,0) -> 0.375 | G2: =SUMIFS('DLC Master Log'!E2:E99,'DLC Master Log'!D2:D99,A2,'DLC Master Log'!G2:G99,"AESTHETIC") -> 59.95 | H2: =SUMIFS('DLC Master Log'!E2:E99,'DLC Master Log'!D2:D99,A2,'DLC Master Log'!G2:G99,"SIMULATION-RICH") -> 99.97 | I2: =G2 -> 59.95 | J2: =H2 -> 99.97 | K2: =COUNTIFS('DLC Master Log'!D:D,A2,'DLC Master Log'!B:B,"Expansion Pack") -> 2 | L2: =COUNTIFS('DLC Master Log'!D:D,A2,'DLC Master Log'!B:B,"Game Pack") -> 2 | M2: =COUNTIFS('DLC Master Log'!D:D,A2,'DLC Master Log'!B:B, "Stuff Pack") -> 4 | N2: =COUNTIFS('DLC Master Log'!D:D,A2,'DLC Master Log'!B:B,"Kit") -> 0 | O2: =SUMIFS('DLC Master Log'!E:E,'DLC Master Log'!D:D,A2,'DLC Master Log'!B:B,"Kit") -> 0
A3: 2016 | B3: =COUNTIFS('DLC Master Log'!D:D,A3,'DLC Master Log'!G:G,"Aesthetic") -> 5 | C3: =COUNTIFS('DLC Master Log'!D:D,A3,'DLC Master Log'!G:G,"Simulation-Rich") -> 2 | D3: =B3+C3 -> 7 | E3: =IFERROR(B3/D3,0) -> 0.71428571 | F3: =IFERROR(C3/D3,0) -> 0.28571429 | G3: =SUMIFS('DLC Master Log'!E3:E100,'DLC Master Log'!D3:D100,A3,'DLC Master Log'!G3:G100,"AESTHETIC") -> 49.95 | H3: =SUMIFS('DLC Master Log'!E3:E100,'DLC Master Log'!D3:D100,A3,'DLC Master Log'!G3:G100,"SIMULATION-RICH") -> 59.98 | I3: =I2+G3 -> 109.9 | J3: =J2+H3 -> 159.95 | K3: =COUNTIFS('DLC Master Log'!D:D,A3,'DLC Master Log'!B:B,"Expansion Pack") -> 1 | L3: =COUNTIFS('DLC Master Log'!D:D,A3,'DLC Master Log'!B:B,"Game Pack") -> 1 | M3: =COUNTIFS('DLC Master Log'!D:D,A3,'DLC Master Log'!B:B, "Stuff Pack") -> 5 | N3: =COUNTIFS('DLC Master Log'!D:D,A3,'DLC Master Log'!B:B,"Kit") -> 0 | O3: =SUMIFS('DLC Master Log'!E:E,'DLC Master Log'!D:D,A3,'DLC Master Log'!B:B,"Kit") -> 0
A4: 2017 | B4: =COUNTIFS('DLC Master Log'!D:D,A4,'DLC Master Log'!G:G,"Aesthetic") -> 1 | C4: =COUNTIFS('DLC Master Log'!D:D,A4,'DLC Master Log'!G:G,"Simulation-Rich") -> 5 | D4: =B4+C4 -> 6 | E4: =IFERROR(B4/D4,0) -> 0.16666667 | F4: =IFERROR(C4/D4,0) -> 0.83333333 | G4: =SUMIFS('DLC Master Log'!E4:E104,'DLC Master Log'!D4:D104,A4,'DLC Master Log'!G4:G104,"AESTHETIC") -> 9.99 | H4: =SUMIFS('DLC Master Log'!E4:E104,'DLC Master Log'!D4:D104,A4,'DLC Master Log'!G4:G104,"SIMULATION-RICH") -> 99.95 | I4: =I3+G4 -> 119.89 | J4: =J3+H4 -> 259.9 | K4: =COUNTIFS('DLC Master Log'!D:D,A4,'DLC Master Log'!B:B,"Expansion Pack") -> 1 | L4: =COUNTIFS('DLC Master Log'!D:D,A4,'DLC Master Log'!B:B,"Game Pack") -> 2 | M4: =COUNTIFS('DLC Master Log'!D:D,A4,'DLC Master Log'!B:B, "Stuff Pack") -> 3 | N4: =COUNTIFS('DLC Master Log'!D:D,A4,'DLC Master Log'!B:B,"Kit") -> 0 | O4: =SUMIFS('DLC Master Log'!E:E,'DLC Master Log'!D:D,A4,'DLC Master Log'!B:B,"Kit") -> 0
A5: 2018 | B5: =COUNTIFS('DLC Master Log'!D:D,A5,'DLC Master Log'!G:G,"Aesthetic") -> 1 | C5: =COUNTIFS('DLC Master Log'!D:D,A5,'DLC Master Log'!G:G,"Simulation-Rich") -> 4 | D5: =B5+C5 -> 5 | E5: =IFERROR(B5/D5,0) -> 0.2 | F5: =IFERROR(C5/D5,0) -> 0.8 | G5: =SUMIFS('DLC Master Log'!E5:E104,'DLC Master Log'!D5:D104,A5,'DLC Master Log'!G5:G104,"AESTHETIC") -> 9.99 | H5: =SUMIFS('DLC Master Log'!E5:E104,'DLC Master Log'!D5:D104,A5,'DLC Master Log'!G5:G104,"SIMULATION-RICH") -> 109.96 | I5: =I4+G5 -> 129.88 | J5: =J4+H5 -> 369.86 | K5: =COUNTIFS('DLC Master Log'!D:D,A5,'DLC Master Log'!B:B,"Expansion Pack") -> 2 | L5: =COUNTIFS('DLC Master Log'!D:D,A5,'DLC Master Log'!B:B,"Game Pack") -> 1 | M5: =COUNTIFS('DLC Master Log'!D:D,A5,'DLC Master Log'!B:B, "Stuff Pack") -> 2 | N5: =COUNTIFS('DLC Master Log'!D:D,A5,'DLC Master Log'!B:B,"Kit") -> 0 | O5: =SUMIFS('DLC Master Log'!E:E,'DLC Master Log'!D:D,A5,'DLC Master Log'!B:B,"Kit") -> 0
A6: 2019 | B6: =COUNTIFS('DLC Master Log'!D:D,A6,'DLC Master Log'!G:G,"Aesthetic") -> 1 | C6: =COUNTIFS('DLC Master Log'!D:D,A6,'DLC Master Log'!G:G,"Simulation-Rich") -> 4 | D6: =B6+C6 -> 5 | E6: =IFERROR(B6/D6,0) -> 0.2 | F6: =IFERROR(C6/D6,0) -> 0.8 | G6: =SUMIFS('DLC Master Log'!E6:E103,'DLC Master Log'!D6:D103,A6,'DLC Master Log'!G6:G103,"AESTHETIC") -> 9.99 | H6: =SUMIFS('DLC Master Log'!E6:E103,'DLC Master Log'!D6:D103,A6,'DLC Master Log'!G6:G103,"SIMULATION-RICH") -> 119.96 | I6: =I5+G6 -> 139.87 | J6: =J5+H6 -> 489.82 | K6: =COUNTIFS('DLC Master Log'!D:D,A6,'DLC Master Log'!B:B,"Expansion Pack") -> 2 | L6: =COUNTIFS('DLC Master Log'!D:D,A6,'DLC Master Log'!B:B,"Game Pack") -> 2 | M6: =COUNTIFS('DLC Master Log'!D:D,A6,'DLC Master Log'!B:B, "Stuff Pack") -> 1 | N6: =COUNTIFS('DLC Master Log'!D:D,A6,'DLC Master Log'!B:B,"Kit") -> 0 | O6: =SUMIFS('DLC Master Log'!E:E,'DLC Master Log'!D:D,A6,'DLC Master Log'!B:B,"Kit") -> 0
A7: 2020 | B7: =COUNTIFS('DLC Master Log'!D:D,A7,'DLC Master Log'!G:G,"Aesthetic") -> 1 | C7: =COUNTIFS('DLC Master Log'!D:D,A7,'DLC Master Log'!G:G,"Simulation-Rich") -> 4 | D7: =B7+C7 -> 5 | E7: =IFERROR(B7/D7,0) -> 0.2 | F7: =IFERROR(C7/D7,0) -> 0.8 | G7: =SUMIFS('DLC Master Log'!E7:E104,'DLC Master Log'!D7:D104,A7,'DLC Master Log'!G7:G104,"AESTHETIC") -> 19.99 | H7: =SUMIFS('DLC Master Log'!E7:E104,'DLC Master Log'!D7:D104,A7,'DLC Master Log'!G7:G104,"SIMULATION-RICH") -> 99.96 | I7: =I6+G7 -> 159.86 | J7: =J6+H7 -> 589.78 | K7: =COUNTIFS('DLC Master Log'!D:D,A7,'DLC Master Log'!B:B,"Expansion Pack") -> 2 | L7: =COUNTIFS('DLC Master Log'!D:D,A7,'DLC Master Log'!B:B,"Game Pack") -> 1 | M7: =COUNTIFS('DLC Master Log'!D:D,A7,'DLC Master Log'!B:B, "Stuff Pack") -> 2 | N7: =COUNTIFS('DLC Master Log'!D:D,A7,'DLC Master Log'!B:B,"Kit") -> 0 | O7: =SUMIFS('DLC Master Log'!E:E,'DLC Master Log'!D:D,A7,'DLC Master Log'!B:B,"Kit") -> 0
A8: 2021 | B8: =COUNTIFS('DLC Master Log'!D:D,A8,'DLC Master Log'!G:G,"Aesthetic") -> 9 | C8: =COUNTIFS('DLC Master Log'!D:D,A8,'DLC Master Log'!G:G,"Simulation-Rich") -> 3 | D8: =B8+C8 -> 12 | E8: =IFERROR(B8/D8,0) -> 0.75 | F8: =IFERROR(C8/D8,0) -> 0.25 | G8: =SUMIFS('DLC Master Log'!E8:E105,'DLC Master Log'!D8:D105,A8,'DLC Master Log'!G8:G105,"AESTHETIC") -> 59.91 | H8: =SUMIFS('DLC Master Log'!E8:E105,'DLC Master Log'!D8:D105,A8,'DLC Master Log'!G8:G105,"SIMULATION-RICH") -> 54.97 | I8: =I7+G8 -> 219.77 | J8: =J7+H8 -> 644.75 | K8: =COUNTIFS('DLC Master Log'!D:D,A8,'DLC Master Log'!B:B,"Expansion Pack") -> 1 | L8: =COUNTIFS('DLC Master Log'!D:D,A8,'DLC Master Log'!B:B,"Game Pack") -> 1 | M8: =COUNTIFS('DLC Master Log'!D:D,A8,'DLC Master Log'!B:B, "Stuff Pack") -> 1 | N8: =COUNTIFS('DLC Master Log'!D:D,A8,'DLC Master Log'!B:B,"Kit") -> 9 | O8: =SUMIFS('DLC Master Log'!E:E,'DLC Master Log'!D:D,A8,'DLC Master Log'!B:B,"Kit") -> 44.91
A9: 2022 | B9: =COUNTIFS('DLC Master Log'!D:D,A9,'DLC Master Log'!G:G,"Aesthetic") -> 8 | C9: =COUNTIFS('DLC Master Log'!D:D,A9,'DLC Master Log'!G:G,"Simulation-Rich") -> 3 | D9: =B9+C9 -> 11 | E9: =IFERROR(B9/D9,0) -> 0.72727273 | F9: =IFERROR(C9/D9,0) -> 0.27272727 | G9: =SUMIFS('DLC Master Log'!E9:E106,'DLC Master Log'!D9:D106,A9,'DLC Master Log'!G9:G106,"AESTHETIC") -> 39.92 | H9: =SUMIFS('DLC Master Log'!E9:E106,'DLC Master Log'!D9:D106,A9,'DLC Master Log'!G9:G106,"SIMULATION-RICH") -> 79.97 | I9: =I8+G9 -> 259.69 | J9: =J8+H9 -> 724.72 | K9: =COUNTIFS('DLC Master Log'!D:D,A9,'DLC Master Log'!B:B,"Expansion Pack") -> 1 | L9: =COUNTIFS('DLC Master Log'!D:D,A9,'DLC Master Log'!B:B,"Game Pack") -> 2 | M9: =COUNTIFS('DLC Master Log'!D:D,A9,'DLC Master Log'!B:B, "Stuff Pack") -> 0 | N9: =COUNTIFS('DLC Master Log'!D:D,A9,'DLC Master Log'!B:B,"Kit") -> 8 | O9: =SUMIFS('DLC Master Log'!E:E,'DLC Master Log'!D:D,A9,'DLC Master Log'!B:B,"Kit") -> 39.92
A10: 2023 | B10: =COUNTIFS('DLC Master Log'!D:D,A10,'DLC Master Log'!G:G,"Aesthetic") -> 9 | C10: =COUNTIFS('DLC Master Log'!D:D,A10,'DLC Master Log'!G:G,"Simulation-Rich") -> 3 | D10: =B10+C10 -> 12 | E10: =IFERROR(B10/D10,0) -> 0.75 | F10: =IFERROR(C10/D10,0) -> 0.25 | G10: =SUMIFS('DLC Master Log'!E10:E107,'DLC Master Log'!D10:D107,A10,'DLC Master Log'!G10:G107,"AESTHETIC") -> 49.91 | H10: =SUMIFS('DLC Master Log'!E10:E107,'DLC Master Log'!D10:D107,A10,'DLC Master Log'!G10:G107,"SIMULATION-RICH") -> 119.97 | I10: =I9+G10 -> 309.6 | J10: =J9+H10 -> 844.69 | K10: =COUNTIFS('DLC Master Log'!D:D,A10,'DLC Master Log'!B:B,"Expansion Pack") -> 3 | L10: =COUNTIFS('DLC Master Log'!D:D,A10,'DLC Master Log'!B:B,"Game Pack") -> 0 | M10: =COUNTIFS('DLC Master Log'!D:D,A10,'DLC Master Log'!B:B, "Stuff Pack") -> 1 | N10: =COUNTIFS('DLC Master Log'!D:D,A10,'DLC Master Log'!B:B,"Kit") -> 8 | O10: =SUMIFS('DLC Master Log'!E:E,'DLC Master Log'!D:D,A10,'DLC Master Log'!B:B,"Kit") -> 39.92
A11: 2024 | B11: =COUNTIFS('DLC Master Log'!D:D,A11,'DLC Master Log'!G:G,"Aesthetic") -> 9 | C11: =COUNTIFS('DLC Master Log'!D:D,A11,'DLC Master Log'!G:G,"Simulation-Rich") -> 2 | D11: =B11+C11 -> 11 | E11: =IFERROR(B11/D11,0) -> 0.81818182 | F11: =IFERROR(C11/D11,0) -> 0.18181818 | G11: =SUMIFS('DLC Master Log'!E11:E108,'DLC Master Log'!D11:D108,A11,'DLC Master Log'!G11:G108,"AESTHETIC") -> 49.91 | H11: =SUMIFS('DLC Master Log'!E11:E108,'DLC Master Log'!D11:D108,A11,'DLC Master Log'!G11:G108,"SIMULATION-RICH") -> 79.98 | I11: =I10+G11 -> 359.51 | J11: =J10+H11 -> 924.67 | K11: =COUNTIFS('DLC Master Log'!D:D,A11,'DLC Master Log'!B:B,"Expansion Pack") -> 2 | L11: =COUNTIFS('DLC Master Log'!D:D,A11,'DLC Master Log'!B:B,"Game Pack") -> 0 | M11: =COUNTIFS('DLC Master Log'!D:D,A11,'DLC Master Log'!B:B, "Stuff Pack") -> 1 | N11: =COUNTIFS('DLC Master Log'!D:D,A11,'DLC Master Log'!B:B,"Kit") -> 8 | O11: =SUMIFS('DLC Master Log'!E:E,'DLC Master Log'!D:D,A11,'DLC Master Log'!B:B,"Kit") -> 39.92
A12: 2025 | B12: =COUNTIFS('DLC Master Log'!D:D,A12,'DLC Master Log'!G:G,"Aesthetic") -> 8 | C12: =COUNTIFS('DLC Master Log'!D:D,A12,'DLC Master Log'!G:G,"Simulation-Rich") -> 4 | D12: =B12+C12 -> 12 | E12: =IFERROR(B12/D12,0) -> 0.66666667 | F12: =IFERROR(C12/D12,0) -> 0.33333333 | G12: =SUMIFS('DLC Master Log'!E12:E109,'DLC Master Log'!D12:D109,A12,'DLC Master Log'!G12:G109,"AESTHETIC") -> 43.92 | H12: =SUMIFS('DLC Master Log'!E12:E109,'DLC Master Log'!D12:D109,A12,'DLC Master Log'!G12:G109,"SIMULATION-RICH") -> 124.96 | I12: =I11+G12 -> 403.43 | J12: =J11+H12 -> 1049.63 | K12: =COUNTIFS('DLC Master Log'!D:D,A12,'DLC Master Log'!B:B,"Expansion Pack") -> 3 | L12: =COUNTIFS('DLC Master Log'!D:D,A12,'DLC Master Log'!B:B,"Game Pack") -> 0 | M12: =COUNTIFS('DLC Master Log'!D:D,A12,'DLC Master Log'!B:B, "Stuff Pack") -> 0 | N12: =COUNTIFS('DLC Master Log'!D:D,A12,'DLC Master Log'!B:B,"Kit") -> 9 | O12: =SUMIFS('DLC Master Log'!E:E,'DLC Master Log'!D:D,A12,'DLC Master Log'!B:B,"Kit") -> 48.91
A13: 2026 | B13: =COUNTIFS('DLC Master Log'!D:D,A13,'DLC Master Log'!G:G,"Aesthetic") -> 3 | C13: =COUNTIFS('DLC Master Log'!D:D,A13,'DLC Master Log'!G:G,"Simulation-Rich") -> 1 | D13: =B13+C13 -> 4 | E13: =IFERROR(B13/D13,0) -> 0.75 | F13: =IFERROR(C13/D13,0) -> 0.25 | G13: =SUMIFS('DLC Master Log'!E13:E110,'DLC Master Log'!D13:D110,A13,'DLC Master Log'!G13:G110,"AESTHETIC") -> 14.97 | H13: =SUMIFS('DLC Master Log'!E13:E110,'DLC Master Log'!D13:D110,A13,'DLC Master Log'!G13:G110,"SIMULATION-RICH") -> 39.99 | I13: =I12+G13 -> 418.4 | J13: =J12+H13 -> 1089.62 | K13: =COUNTIFS('DLC Master Log'!D:D,A13,'DLC Master Log'!B:B,"Expansion Pack") -> 1 | L13: =COUNTIFS('DLC Master Log'!D:D,A13,'DLC Master Log'!B:B,"Game Pack") -> 0 | M13: =COUNTIFS('DLC Master Log'!D:D,A13,'DLC Master Log'!B:B, "Stuff Pack") -> 0 | N13: =COUNTIFS('DLC Master Log'!D:D,A13,'DLC Master Log'!B:B,"Kit") -> 3 | O13: =SUMIFS('DLC Master Log'!E:E,'DLC Master Log'!D:D,A13,'DLC Master Log'!B:B,"Kit") -> 14.97
A14: TOTALS | B14: =SUM(B2:B13) -> 60 | C14: =SUM(C2:C13) -> 38 | D14: =SUM(D2:D13) -> 98 | G14: =SUM(G2:G13) -> 418.4 | H14: =SUM(H2:H13) -> 1089.62 | K14: =SUM(K2:K13) -> 21 | L14: =SUM(L2:L13) -> 12 | M14: =SUM(M2:M13) -> 20 | N14: =SUM(N2:N13) -> 45 | O14: =SUM(O2:O13) -> 228.55

Sheet Retail Value Summary
A1: Pack Type | B1: Total Packs Released | C1: Total Retail Value (Launch Prices) | D1: Average Price Per Pack | E1: % of Total Packs | F1: % of Total Retail Value
A2: Expansion Pack | B2: =COUNTIFS('DLC Master Log'!B:B, "Expansion Pack") -> 21 | C2: =SUMIF('DLC Master Log'!B:B,"Expansion Pack",'DLC Master Log'!E:E) -> 839.79 | D2: =C2/B2 -> 39.99 | E2: =B2/$B$6 -> 0.21428571 | F2: =C2/$C$6 -> 0.55688253
A3: Game Pack | B3: =COUNTIFS('DLC Master Log'!B:B,"Game Pack") -> 12 | C3: =SUMIF('DLC Master Log'!B:B,"Game Pack",'DLC Master Log'!E:E) -> 239.88 | D3: =C3/B3 -> 19.99 | E3: =B3/$B$6 -> 0.12244898 | F3: =C3/$C$6 -> 0.15906951
A4: Stuff Pack | B4: =COUNTIFS('DLC Master Log'!B:B,"Stuff Pack") -> 20 | C4: =SUMIF('DLC Master Log'!B:B,"Stuff Pack",'DLC Master Log'!E:E) -> 199.8 | D4: =C4/B4 -> 9.99 | E4: =B4/$B$6 -> 0.20408163 | F4: =C4/$C$6 -> 0.13249161
A5: Kit | B5: =COUNTIFS('DLC Master Log'!B:B,"Kit") -> 45 | C5: =SUMIF('DLC Master Log'!B:B,"Kit",'DLC Master Log'!E:E) -> 228.55 | D5: =C5/B5 -> 5.0788889 | E5: =B5/$B$6 -> 0.45918367 | F5: =C5/$C$6 -> 0.15155635
A6: TOTALS | B6: =SUM(B2:B5) -> 98 | C6: =SUM(C2:C5) -> 1508.02

Sheet Pivot Tables Pack Type Analysis
A1: Count of Pack Name | C1: Release Year
A2: Pack Type | B2: Content Category | C2: 2015 | D2: 2016 | E2: 2017 | F2: 2018 | G2: 2019 | H2: 2020 | I2: 2021 | J2: 2022 | K2: 2023 | L2: 2024 | M2: 2025 | N2: 2026 | O2: Grand Total
A3: Expansion Pack | B3: Simulation-Rich | C3: 2 | D3: 1 | E3: 1 | F3: 2 | G3: 2 | H3: 2 | I3: 1 | J3: 1 | K3: 3 | L3: 2 | M3: 3 | N3: 1 | O3: 21
A4: Game Pack | B4: Aesthetic | C4: 1 | H4: 1 | I4: 1 | O4: 3
B5: Simulation-Rich | C5: 1 | D5: 1 | E5: 2 | F5: 1 | G5: 2 | J5: 2 | O5: 9
A6: Kit | B6: Aesthetic | I6: 8 | J6: 8 | K6: 8 | L6: 8 | M6: 8 | N6: 3 | O6: 43
B7: Simulation-Rich | I7: 1 | M7: 1 | O7: 2
A8: Stuff Pack | B8: Aesthetic | C8: 4 | D8: 5 | E8: 1 | F8: 1 | G8: 1 | K8: 1 | L8: 1 | O8: 14
B9: Simulation-Rich | E9: 2 | F9: 1 | H9: 2 | I9: 1 | O9: 6
A10: Grand Total | C10: 8 | D10: 7 | E10: 6 | F10: 5 | G10: 5 | H10: 5 | I10: 12 | J10: 11 | K10: 12 | L10: 11 | M10: 12 | N10: 4 | O10: 98
A15: Sum of Launch Price USD | B15: Release Year
A16: Pack Type | B16: 2015 | C16: 2016 | D16: 2017 | E16: 2018 | F16: 2019 | G16: 2020 | H16: 2021 | I16: 2022 | J16: 2023 | K16: 2024 | L16: 2025 | M16: 2026 | N16: Grand Total
A17: Expansion Pack | B17: 79.98 | C17: 39.99 | D17: 39.99 | E17: 79.98 | F17: 79.98 | G17: 79.98 | H17: 39.99 | I17: 39.99 | J17: 119.97 | K17: 79.98 | L17: 119.97 | M17: 39.99 | N17: 839.79
A18: Game Pack | B18: 39.98 | C18: 19.99 | D18: 39.98 | E18: 19.99 | F18: 39.98 | G18: 19.99 | H18: 19.99 | I18: 39.98 | N18: 239.88
A19: Kit | H19: 44.91 | I19: 39.92 | J19: 39.92 | K19: 39.92 | L19: 48.91 | M19: 14.97 | N19: 228.55
A20: Stuff Pack | B20: 39.96 | C20: 49.95 | D20: 29.97 | E20: 19.98 | F20: 9.99 | G20: 19.98 | H20: 9.99 | J20: 9.99 | K20: 9.99 | N20: 199.8
A21: Grand Total | B21: 159.92 | C21: 109.93 | D21: 109.94 | E21: 119.95 | F21: 129.95 | G21: 119.95 | H21: 114.88 | I21: 119.89 | J21: 169.88 | K21: 129.89 | L21: 168.88 | M21: 54.96 | N21: 1508.02

Sheet Cost Summary
A1: Game | B1: Base Game Price | C1: Total DLC Cost | D1: Total Cost To Own | E1: DLC Pack Count
A2: The Sims 3 (2009) | B2: 49.99 | C2: 609.8 | D2: 659.79 | E2: 20
A3: The Sims 4 Launch (2014) | B3: 59.99 | C3: 0 | D3: 59.99 | E3: 0
A4: The Sims 4 Full Game (2026) | B4: 59.99 | C4: 1508.02 | D4: 1568.01 | E4: 98
A5: inZOI (2025) | B5: 39.99 | C5: 0 | D5: 39.99 | E5: 0
A6: Paralives (2026) | B6: 39.99 | C6: 0 | D6: 39.99 | E6: 0

Sheet Feature Data
A1: Feature Category | B1: Feature Type | C1: Feature Name | D1: Game | E1: Availability
A2: World & Navigation | B2: Core | C2: Open World | D2: The Sims 3 (2009) | E2: YES
A3: World & Navigation | B3: Core | C3: Open World | D3: The Sims 4 Launch (2014) | E3: NO
A4: World & Navigation | B4: Core | C4: Open World | D4: The Sims 4 Base Game Now (2026) | E4: NO
A5: World & Navigation | B5: Core | C5: Open World | D5: The Sims 4 Full Game (2026) | E5: NO
A6: World & Navigation | B6: Core | C6: Open World | D6: inZOI (2025) | E6: YES
A7: World & Navigation | B7: Core | C7: Open World | D7: Paralives (2026) | E7: YES
A8: World & Navigation | B8: Core | C8: Driveable Cars | D8: The Sims 3 (2009) | E8: YES
A9: World & Navigation | B9: Core | C9: Driveable Cars | D9: The Sims 4 Launch (2014) | E9: NO
A10: World & Navigation | B10: Core | C10: Driveable Cars | D10: The Sims 4 Base Game Now (2026) | E10: NO
A11: World & Navigation | B11: Core | C11: Driveable Cars | D11: The Sims 4 Full Game (2026) | E11: NO
A12: World & Navigation | B12: Core | C12: Driveable Cars | D12: inZOI (2025) | E12: YES
... A139: Pets | B139: Expected | C139: Pets | D139: Paralives (2026) | E139: NO

Sheet Definitions
A1: SECTION 1 : PROJECT DEFINITIONS
A3: Term | B3: Definition
A4: DLC | B4: Downloadable Content: any paid content released for The Sims 4 after the base game. Included Expansion Packs, Game Packs, Stuff Packs and Kits.
A5: Base Game | B5: The core game purchased at launch. Not considered DLC. Recorded separately in all cost calculations.
A6: Launch Price | B6: The standard USD retail price of a pack on its first day of release. Used consistently across all cost calculations regardless of subsequent price changes, discounts, or bundle pricing.
A7: Total Cost to Own | B7: The combined cost of all the base game plus all individual DLC packs at their launch prices. Does not include bundle discounts, sale prices, or subscription pricing.
A10: SECTION 2: CONTENT CATEGORY DEFINITIONS
A12: Category | B12: Definition | C12: Classification Rule
A13: AESTHETIC | B13: A pack whose primary purpose is to add visual content (clothing, furniture, décor, or build objects) without introducing a new gameplay system, mechanic, or simulation feature | C13: If removing all new items would leave the game playing identically, it is AESTHETIC
A14: SIMULATION-RICH | B14: A pack whose primary purpose is to introduce a new gameplay system, mechanic, life stage, career with genuine depth, or world feature that changes how the game functions. | C14: If the pack introduces something that changes what a Sim can do or experience in a meaningful way, it is SIMULATION-RICH
A17: SECTION 3: PACK TYPE DEFINITIONS
A19: Pack Type | B19: Definition
A20: Expansion Pack | B20: EA's premium DLC tier. Introduces a new world and multiple new gameplay systems.
A21: Game Pack | B21: Mid-tier DLC. Focuses on one specific gameplay theme or mechanic.
A22: Stuff Pack | B22: Lower tier DLC. Primarily adds new objects, clothing, and décor with minimal gameplay additions.
A23: Kit | B23: EA's lowest tier DLC introduced in 2021. Almost exclusively cosmetic content (new clothing and buy items).
A24: Creator Kit | B24: A Kit designed by a community creator in collaboration with EA. Excluded from this dataset as it represents community-designed content rather than an internal EA content strategy decision.
A27: SECTION 4: FEATURE & COST COMPARISON DEFINITIONS
A29: Term | B29: Definition
A30: YES | B30: The feature is fully available in the game at the version being assessed (either base game at launch or current full game.)
A31: NO | B31: The feature is not available in the gane at the version being assessed.
A32: PARTIAL | B32: The game has a limited, shallow, or incomplete version of the feature. It exists but does not fully deliver on the feature's potential.
A33: The Sims 3 Launch (2009) | B33: The Sims 3 base game as released on June 2, 2009. Reflects only what was included at launch without any expansion or stuff packs
A34: The Sims 4 Launch (2014) | B34: The Sims 4 base game as released on September 2, 2024. Reflects only what was included on day one.
A35: The Sims 4 Base Game Now (2026) | B35: The Sims 4 base game as it exists in March 2026 following all free updates and patches. Does not include any paid DLC content.
A36: The Sims 4 Full Game (2026) | B36: The Sims 4 as it exists in March 2026 with every paid DLC pack included. Represents the maximum possible game experience at a total cost of $1,568.01.
A37: inZOI (2025) | B37: inZOI as released on March 28, 2025 during Early Access. Reflects launch features only.
A38: Paralives (2026) | B38: Paralives as released on May 25 2026 during Early Acccess. Reflects launch features only. (Planned)
A41: SECTION 5: FEATURE TYPE DEFINITIONS
A43: Feature Type | B43: Definition
A44: Core | B44: A feature so fundamental to the life simulation genre that its absense undermines the game's core promise. Every life simulator should have this
A45: Expected | B45: A feature that players reasonable expect based on genre conventions and predecessor titles. Its absence is notable and disappointing but does not entirely breack the simulation promise.
A46: Bonus | B46: A feature that meaningfully enriches the experience but whose absence does not fundamentally undermine the life simulation promise.
A49: SECTION 6: FAN REQUESTS DEFINITIONS
A51: Term | B51: Definition
A52: Earliest Verified Request | B52: The oldest forum post, Reddit thread, social media,or new article found during research that documents the community requesting this feature. Does not claim to be the asolute first time the feature was ever requested.
A53: Never Added | B53: The feature has not been added to The Sims 4 in any form as of 2026.
A54: Added Late | B54: The feature was eventually added to The Sims 4 but only after a significant period of community requests (typically two or more years after first being widely requested).
A55: Partially Added | B55: A limited or shallow version of the feature was added but the full implementation players requested has never been delivered.
A56: Years Ignored | B56: Calculated ising the formula =IF(D2-="Never Added",YEAR(TODAY())-C2,IF(D2="Partially Added",YEAR(TODAY())-C2,E2-C2)). Represents the number of years between the earliest verified request and either the current year for undelivered features of the year the feature was added for late additions.
...
